<?xml version="1.0"?>
<robot name="my_robot">
    <material name="white">
        <color rgba="1.0 1.0 1.0 0.75" />
    </material>

    <material name="blue">
        <color rgba="0.0 0.5 1.0 0.75" />
    </material>

    <material name="green">
        <color rgba="0.0 1.0 0.5 0.75" />
    </material>

    <link name="base_footprint"/>

    <link name="base_link">
        <visual>
            <origin xyz="0 0 0.3" rpy="0 0 0"/>
            <geometry>
                <cylinder length="0.6" radius="0.2"/>
            </geometry>
            <material name="white"/>
        </visual>
    </link>

    <link name="sphere_link">
        <visual>
            <origin xyz="0 0 0.0" rpy="0 0 0"/>
            <geometry>
                <sphere radius="0.2"/>
            </geometry>
            <material name="blue"/>
        </visual>
    </link>

    <link name="left_wheel">
        <visual>
            <origin xyz="0.0 0 0" rpy="1.57079 0.0 0.0"/>
            <geometry>
                <cylinder radius="0.1" length="0.05"/>
            </geometry>
            <material name="green"/>
        </visual>
    </link>

    <link name="right_wheel">
        <visual>
            <origin xyz="0.0 0.0 0" rpy="1.57079 0.0 0.0"/>
            <geometry>
                <cylinder radius="0.1" length="0.05"/>
            </geometry>
            <material name="green"/>
        </visual>
    </link>

    <joint name="base_joint" type="fixed">
        <origin xyz="0.0 0.0 0.1" rpy="0.0 0.0 0.0"/>
        <parent link="base_footprint"/>
        <child link="base_link"/>
    </joint>

    <joint name="base_sphere" type="fixed">
        <origin xyz="0.0 0.0 0.6" rpy="0 0 0"/>
        <parent link="base_link"/>
        <child link="sphere_link"/>
    </joint>

    <joint name="base_left_wheel_joint" type="continuous">
        <origin xyz="0.0 0.225 0.0" rpy="0.0 0.0 0.0"/>
        <parent link="base_link"/>
        <child link="left_wheel"/>
        <axis xyz="0.0 1.0 0.0"/>
    </joint>

    <joint name="base_right_wheel_joint" type="continuous">
        <origin xyz="0.0 -0.225 0.0" rpy="0.0 0.0 0.0"/>
        <parent link="base_link"/>
        <child link="right_wheel"/>
        <axis xyz="0.0 1.0 0.0"/>
    </joint>
</robot>
